Workbook

Sheet position reconstruction
C1: Reconstruction fit, using identified impedance parameters with ARX method
D3: delay (ms) | M3: * virtual force estimation
D4: 9 | F4: 10 | H4: 11 | J4: 12
B5: Method* | C5: Cycle phase | D5: average | E5: std | F5: average | G5: std | H5: average | I5: std | J5: average | K5: std
B6: filter+ | C6: Upper | D6: 0.69765241 | E6: 0.1921935 | F6: 0.70449994 | G6: 0.18364111 | H6: 0.70578854 | I6: 0.17718257 | J6: 0.65998421 | K6: 0.22800759 | M6: Default parameters for force estimation:
C7: Decreasing | D7: 0.8002505 | E7: 0.063377976 | F7: 0.8136217 | G7: 0.053641853 | H7: 0.81678975 | I7: 0.05972866 | J7: 0.82431879 | K7: 0.049510845 | M7: n = 4 | N7: lc = 1
C8: Lower | D8: 0.68461466 | E8: 0.1716067 | F8: 0.69608985 | G8: 0.16879255 | H8: 0.70269735 | I8: 0.17533738 | J8: 0.70487652 | K8: 0.18264706 | M8: The number in front of "sine" indicates the value of n
B9: SineOpt+ | C9: Upper | D9: 0.47714949 | E9: 0.29758604 | F9: 0.46018321 | G9: 0.35443825 | H9: 0.46892778 | I9: 0.27472117 | J9: 0.44495622 | K9: 0.36856614 | M9: If the name contains Nlc it indicates that lc = 0
C10: Decreasing | D10: 0.74137852 | E10: 0.14406627 | F10: 0.68402761 | G10: 0.23754813 | H10: 0.80741551 | I10: 0.10223444 | J10: 0.72917345 | K10: 0.19816125
C11: Lower | D11: 0.53133524 | E11: 0.27879164 | F11: 0.50720837 | G11: 0.29716429 | H11: 0.56080433 | I11: 0.28522355 | J11: 0.49035277 | K11: 0.32006834
B12: 5sineOpt+ | C12: Upper | D12: 0.38049451 | E12: 0.41775332 | F12: 0.47259325 | G12: 0.37087376 | H12: 0.30643557 | I12: 0.54601436 | J12: 0.46114193 | K12: 0.38247645
C13: Decreasing | D13: 0.6266201 | E13: 0.24375103 | F13: 0.68983522 | G13: 0.18972249 | H13: 0.75284215 | I13: 0.16017691 | J13: 0.36987837 | K13: 0.48640684
C14: Lower | D14: 0.49284629 | E14: 0.3121973 | F14: 0.46558852 | G14: 0.32696525 | H14: 0.40728412 | I14: 0.40058117 | J14: 0.42115208 | K14: 0.35742119 | M14: Opt+ means that a multi start was done only once per experiment,
B15: 5sineNlcOpt+ | C15: Upper | D15: 0.46432477 | E15: 0.32057118 | F15: 0.41362818 | G15: 0.4035656 | H15: 0.27819825 | I15: 0.51101794 | J15: 0.32271634 | K15: 0.52596338 | M15: providing the initial value for all the estimation
C16: Decreasing | D16: 0.64012559 | E16: 0.20526879 | F16: 0.69251185 | G16: 0.17821508 | H16: 0.54445433 | I16: 0.34425762 | J16: 0.52291841 | K16: 0.34602575 | M16: OptM means that multi starts were done at each estimation
C17: Lower | D17: 0.42105243 | E17: 0.33402514 | F17: 0.46826916 | G17: 0.35011276 | H17: 0.42925672 | I17: 0.36348194 | J17: 0.47654729 | K17: 0.3241863
B18: 3sineOpt+ | C18: Upper | D18: 0.59088029 | E18: 0.26940908 | F18: 0.56413751 | G18: 0.2990751 | H18: 0.5739578 | I18: 0.29749472 | J18: 0.56008922 | K18: 0.29875351
C19: Decreasing | D19: 0.77036903 | E19: 0.078333281 | F19: 0.71187682 | G19: 0.16657498 | H19: 0.78063467 | I19: 0.08838266 | J19: 0.73073178 | K19: 0.14745338 | M19: Fit equation :
C20: Lower | D20: 0.5732911 | E20: 0.22949708 | F20: 0.52495266 | G20: 0.28824289 | H20: 0.57657606 | I20: 0.25119779 | J20: 0.5008924 | K20: 0.3493796
B21: 3sineNlcOpt+ | C21: Upper | D21: 0.57647379 | E21: 0.29491101 | F21: 0.58521584 | G21: 0.31316807 | H21: 0.53206913 | I21: 0.28222161 | J21: 0.53840022 | K21: 0.33164128 | N21: is the reconstruction error
C22: Decreasing | D22: 0.78350541 | E22: 0.079153363 | F22: 0.77007217 | G22: 0.12103516 | H22: 0.79382247 | I22: 0.084861012 | J22: 0.79410752 | K22: 0.086837257 | N22: is the measured output
C23: Lower | D23: 0.54938262 | E23: 0.2916971 | F23: 0.50715502 | G23: 0.29409311 | H23: 0.5996706 | I23: 0.24971546 | J23: 0.57262717 | K23: 0.28120556
B24: sineOptM | C24: Upper | D24: 0.53715187 | E24: 0.28627654 | F24: 0.52904923 | G24: 0.30712807 | H24: 0.52954273 | I24: 0.32247839 | J24: 0.39395217 | K24: 0.45181831 | M24: Corrélation between average fit and standard deviation of the fits
C25: Decreasing | D25: 0.76043164 | E25: 0.10614499 | F25: 0.76056824 | G25: 0.13352019 | H25: 0.76276432 | I25: 0.12940615 | J25: 0.73581312 | K25: 0.18070747 | M25: delay (ms) | N25: 9 | O25: 10 | P25: 11 | Q25: 12
C26: Lower | D26: 0.59864738 | E26: 0.22972288 | F26: 0.57817332 | G26: 0.25805189 | H26: 0.54317552 | I26: 0.29445252 | J26: 0.5281941 | K26: 0.32716147 | M26: correlation | N26: =CORREL(D6:D38,E6:E38) -> -0.97302731 | O26: =CORREL(F6:F38,G6:G38) -> -0.97515099 | P26: =CORREL(H6:H38,I6:I38) -> -0.97903823 | Q26: =CORREL(J6:J38,K6:K38) -> -0.98135804
B27: 3sineNlcOptM | C27: Upper | D27: 0.66700625 | E27: 0.2141401 | F27: 0.6297059 | G27: 0.25896165 | H27: 0.67850379 | I27: 0.20830517 | J27: 0.64121609 | K27: 0.24139199
C28: Decreasing | D28: 0.79112591 | E28: 0.068001138 | F28: 0.80034731 | G28: 0.073813577 | H28: 0.82132263 | I28: 0.057967257 | J28: 0.81923529 | K28: 0.055915 | M28: Strong inverse correlation between average and standard deviation
C29: Lower | D29: 0.68529635 | E29: 0.16226892 | F29: 0.7029482 | G29: 0.1541066 | H29: 0.69465395 | I29: 0.17034528 | J29: 0.65754324 | K29: 0.23316282
B30: 3sineOptM | C30: Upper | D30: 0.67800059 | E30: 0.21639756 | F30: 0.70023757 | G30: 0.18550488 | H30: 0.66253542 | I30: 0.23024536 | J30: 0.61098317 | K30: 0.27774808 | N30: Nb samples per cycle phase | R30: The phase cycle are sorted
C31: Decreasing | D31: 0.80177187 | E31: 0.069674854 | F31: 0.80952484 | G31: 0.062133939 | H31: 0.8180044 | I31: 0.063519086 | J31: 0.81928806 | K31: 0.055471729 | M31: Upper | N31: 55 | R31: online (based on the previous
C32: Lower | D32: 0.69409094 | E32: 0.13465061 | F32: 0.69326541 | G32: 0.16266642 | H32: 0.70949591 | I32: 0.15204941 | J32: 0.69369991 | K32: 0.17662677 | M32: Decreas. | N32: 48 | R32: cycles duration)
B33: 2sineNlcOptM | C33: Upper | D33: 0.48387179 | E33: 0.30761165 | F33: 0.55053769 | G33: 0.2728235 | H33: 0.52371048 | I33: 0.32932733 | J33: 0.47913077 | K33: 0.33704802 | M33: Lower | N33: 62
C34: Decreasing | D34: 0.79072476 | E34: 0.06268339 | F34: 0.79120802 | G34: 0.076602533 | H34: 0.79239709 | I34: 0.085634578 | J34: 0.80143266 | K34: 0.076514809 | M34: total | N34: =SUM(N31:N33) -> 165
C35: Lower | D35: 0.67581001 | E35: 0.16451778 | F35: 0.70048428 | G35: 0.14891103 | H35: 0.64669253 | I35: 0.2252297 | J35: 0.68285662 | K35: 0.15858726
B36: 2sineOptM | C36: Upper | D36: 0.709602 | E36: 0.17015531 | F36: 0.63299837 | G36: 0.24420431 | H36: 0.61109269 | I36: 0.27988189 | J36: 0.54317442 | K36: 0.34552198
C37: Decreasing | D37: 0.8057192 | E37: 0.054095218 | F37: 0.81056908 | G37: 0.056543648 | H37: 0.82303488 | I37: 0.05182784 | J37: 0.82448853 | K37: 0.04807993
C38: Lower | D38: 0.71147955 | E38: 0.14341852 | F38: 0.72369982 | G38: 0.14727527 | H38: 0.72488356 | I38: 0.16119671 | J38: 0.69984736 | K38: 0.18916142

Sheet position reconstruction 2
C1: Reconstruction fit, using identified impedance parameters with ARX method
D3: delay (ms) | AC3: * virtual force estimation
D4: 5 | F4: 6 | H4: 7 | J4: 8 | L4: 9 | N4: 10 | P4: 11 | R4: 12 | T4: 13 | V4: 14 | X4: 15 | Z4: Total
B5: Method* | C5: Cycle phase | D5: average | E5: std | F5: average | G5: std | H5: average | I5: std | J5: average | K5: std | L5: average | M5: std | N5: average | O5: std | P5: average | Q5: std | R5: average | S5: std | T5: average | U5: std | V5: average | W5: std | X5: average | Y5: std | Z5: average | AA5: std
B6: filter+ | C6: Upper | D6: 0.55433421 | E6: 0.26466798 | F6: 0.59299412 | G6: 0.24707541 | H6: 0.59392431 | I6: 0.27343827 | J6: 0.62810507 | K6: 0.25241866 | L6: 0.67380046 | M6: 0.21276296 | N6: 0.70024264 | O6: 0.18627573 | P6: 0.70449659 | Q6: 0.18542188 | R6: 0.65222215 | S6: 0.24727188 | T6: 0.6347846 | U6: 0.25223526 | V6: 0.59885845 | W6: 0.28052869 | X6: 0.53754306 | Y6: 0.32568959 | Z6: 0.60748442 | AA6: 0.27067324 | AC6: Default parameters for force estimation:
C7: Decreasing | D7: 0.74563718 | E7: 0.083377996 | F7: 0.76348126 | G7: 0.07846596 | H7: 0.7795314 | I7: 0.072594956 | J7: 0.79254593 | K7: 0.066769237 | L7: 0.80066938 | M7: 0.068231091 | N7: 0.8159573 | O7: 0.052399291 | P7: 0.81789457 | Q7: 0.055020769 | R7: 0.81341249 | S7: 0.060743243 | T7: 0.79917336 | U7: 0.067772447 | V7: 0.76528187 | W7: 0.093280767 | X7: 0.70346632 | Y7: 0.13940324 | Z7: 0.7827028 | AA7: 0.080390805 | AC7: n = 4 | AD7: lc = 1
C8: Lower | D8: 0.58013498 | E8: 0.24173231 | F8: 0.59807662 | G8: 0.23872977 | H8: 0.63127796 | I8: 0.21030074 | J8: 0.64824521 | K8: 0.20278854 | L8: 0.67626389 | M8: 0.17709298 | N8: 0.6896789 | O8: 0.17185263 | P8: 0.70056271 | Q8: 0.170756 | R8: 0.6841704 | S8: 0.20101813 | T8: 0.68485462 | U8: 0.19031228 | V8: 0.65391566 | W8: 0.21743049 | X8: 0.56350354 | Y8: 0.29511962 | Z8: 0.64939567 | AA8: 0.20893244 | AC8: The number in front of "sine" indicates the value of n
B9: SineOpt+ | C9: Upper | D9: 0.46553523 | E9: 0.25328808 | F9: 0.37308005 | G9: 0.30662721 | H9: 0.49936233 | I9: 0.27475015 | J9: 0.38503381 | K9: 0.39542726 | L9: 0.46440239 | M9: 0.31455029 | N9: 0.46435762 | O9: 0.35982438 | P9: 0.45607259 | Q9: 0.32163468 | R9: 0.43093792 | S9: 0.38967543 | T9: 0.19536982 | U9: 0.63898157 | V9: 0.12505308 | W9: 0.78112971 | X9: 0.056763636 | Y9: 0.74086142 | Z9: 0.39128959 | AA9: 0.38578571 | AC9: If the name contains Nlc it indicates that lc = 0
C10: Decreasing | D10: 0.66896493 | E10: 0.12249393 | F10: 0.68986677 | G10: 0.11281575 | H10: 0.68744833 | I10: 0.15016852 | J10: 0.72348328 | K10: 0.13259892 | L10: 0.64336644 | M10: 0.23657799 | N10: 0.60633839 | O10: 0.28505902 | P10: 0.78978628 | Q10: 0.12383454 | R10: 0.68601751 | S10: 0.22948697 | T10: 0.51939361 | U10: 0.35043407 | V10: 0.61862116 | W10: 0.2452925 | X10: 0.43108448 | Y10: 0.41697937 | Z10: 0.63968644 | AA10: 0.22786166
C11: Lower | D11: 0.45802944 | E11: 0.3020003 | F11: 0.48206233 | G11: 0.29572952 | H11: 0.50092734 | I11: 0.27276386 | J11: 0.5567106 | K11: 0.24036008 | L11: 0.53898484 | M11: 0.28071755 | N11: 0.49628615 | O11: 0.29974601 | P11: 0.54005602 | Q11: 0.29890865 | R11: 0.49739302 | S11: 0.29993191 | T11: 0.46894613 | U11: 0.38098155 | V11: 0.36637072 | W11: 0.44418774 | X11: 0.32369021 | Y11: 0.40965388 | Z11: 0.49005511 | AA11: 0.30659978
B12: 5sineOpt+ | C12: Upper | D12: 0.35800134 | E12: 0.33034961 | F12: 0.42689927 | G12: 0.33325497 | H12: 0.46149491 | I12: 0.3199996 | J12: 0.46759072 | K12: 0.31586478 | L12: 0.32450028 | M12: 0.45349223 | N12: 0.47531047 | O12: 0.34504022 | P12: 0.15341885 | Q12: 0.67944434 | R12: 0.284729 | S12: 0.59297175 | T12: 0.41534418 | U12: 0.45383517 | V12: 0.12166859 | W12: 0.69338065 | X12: -0.072758633 | Y12: 0.79994547 | Z12: 0.35539536 | AA12: 0.43575215
C13: Decreasing | D13: 0.57618601 | E13: 0.22249012 | F13: 0.58124018 | G13: 0.26044359 | H13: 0.6918604 | I13: 0.10073704 | J13: 0.69963425 | K13: 0.15647553 | L13: 0.59586707 | M13: 0.26377035 | N13: 0.62335328 | O13: 0.24874767 | P13: 0.66170362 | Q13: 0.24644508 | R13: 0.39397713 | S13: 0.47176433 | T13: 0.34857795 | U13: 0.43684283 | V13: 0.18595522 | W13: 0.6202602 | X13: 0.13693257 | Y13: 0.65226006 | Z13: 0.53841884 | AA13: 0.31600807
C14: Lower | D14: 0.49049351 | E14: 0.24137337 | F14: 0.52626505 | G14: 0.21967304 | H14: 0.45865139 | I14: 0.30855617 | J14: 0.45716973 | K14: 0.34131198 | L14: 0.49126329 | M14: 0.31081984 | N14: 0.47950505 | O14: 0.33042745 | P14: 0.42640918 | Q14: 0.39313651 | R14: 0.41289377 | S14: 0.35041875 | T14: 0.28661543 | U14: 0.45362548 | V14: 0.35196633 | W14: 0.40683868 | X14: 0.14619499 | Y14: 0.52138419 | Z14: 0.41257195 | AA14: 0.35783156 | AC14: Opt+ means that a multi start was done only once per experiment,
B15: 5sineNlcOpt+ | C15: Upper | D15: 0.36882833 | E15: 0.31465189 | F15: 0.37428819 | G15: 0.39072707 | H15: 0.37493316 | I15: 0.39939135 | J15: 0.42163588 | K15: 0.3336884 | L15: 0.439401 | M15: 0.33152382 | N15: 0.43979157 | O15: 0.38720312 | P15: 0.2858412 | Q15: 0.55375367 | R15: 0.31139014 | S15: 0.57146405 | T15: 0.26423341 | U15: 0.53308397 | V15: 0.20193547 | W15: 0.60625936 | X15: 0.16664774 | Y15: 0.72075045 | Z15: 0.36046295 | AA15: 0.42571135 | AC15: providing the initial value for the rest of estimations
C16: Decreasing | D16: 0.59745007 | E16: 0.15408575 | F16: 0.64958781 | G16: 0.13736094 | H16: 0.66723062 | I16: 0.14685269 | J16: 0.59529302 | K16: 0.23753759 | L16: 0.6374623 | M16: 0.20557987 | N16: 0.67255401 | O16: 0.19319207 | P16: 0.50526338 | Q16: 0.36652656 | R16: 0.5350157 | S16: 0.32096986 | T16: 0.33221987 | U16: 0.46167213 | V16: 0.31450598 | W16: 0.48610115 | X16: 0.36733331 | Y16: 0.51989463 | Z16: 0.5639666 | AA16: 0.2736852 | AC16: OptM means that multi starts were done at each estimation
C17: Lower | D17: 0.47794534 | E17: 0.24051303 | F17: 0.49497037 | G17: 0.25021972 | H17: 0.46357093 | I17: 0.28728448 | J17: 0.41250128 | K17: 0.37176105 | L17: 0.41784337 | M17: 0.30728034 | N17: 0.43528567 | O17: 0.34888009 | P17: 0.42751554 | Q17: 0.35395757 | R17: 0.4743523 | S17: 0.32001237 | T17: 0.35820464 | U17: 0.40439404 | V17: 0.14092567 | W17: 0.56812455 | X17: 0.28019556 | Y17: 0.40754403 | Z17: 0.40583938 | AA17: 0.34765014
B18: 3sineOpt+ | C18: Upper | D18: 0.48485776 | E18: 0.2797095 | F18: 0.53726118 | G18: 0.24357697 | H18: 0.55489509 | I18: 0.22835642 | J18: 0.50579122 | K18: 0.31130879 | L18: 0.59813268 | M18: 0.25531405 | N18: 0.56953941 | O18: 0.28555899 | P18: 0.57843655 | Q18: 0.31047174 | R18: 0.57039623 | S18: 0.30033609 | T18: 0.53812681 | U18: 0.33362423 | V18: 0.52220016 | W18: 0.35721783 | X18: 0.26585613 | Y18: 0.62697021 | Z18: 0.52584602 | AA18: 0.31127665
C19: Decreasing | D19: 0.66797388 | E19: 0.12807145 | F19: 0.69120798 | G19: 0.11310002 | H19: 0.70490649 | I19: 0.11419901 | J19: 0.74538232 | K19: 0.084760622 | L19: 0.76871263 | M19: 0.09520582 | N19: 0.75313978 | O19: 0.12355725 | P19: 0.79101866 | Q19: 0.075274262 | R19: 0.72580214 | S19: 0.1503222 | T19: 0.66440269 | U19: 0.19923804 | V19: 0.58932876 | W19: 0.25611018 | X19: 0.50090802 | Y19: 0.33383937 | Z19: 0.69752893 | AA19: 0.15625848 | AC19: Fit equation :
C20: Lower | D20: 0.52575287 | E20: 0.19932714 | F20: 0.50276129 | G20: 0.23046504 | H20: 0.50855413 | I20: 0.26594282 | J20: 0.52693007 | K20: 0.2547323 | L20: 0.56874833 | M20: 0.21599506 | N20: 0.50154758 | O20: 0.28984995 | P20: 0.58493616 | Q20: 0.2398629 | R20: 0.48132982 | S20: 0.36297821 | T20: 0.53942752 | U20: 0.29778066 | V20: 0.40110608 | W20: 0.40786838 | X20: 0.42188276 | Y20: 0.37544255 | Z20: 0.51468427 | AA20: 0.27786324
B21: 3sineNlcOpt+ | C21: Upper | D21: 0.34319624 | E21: 0.33312007 | F21: 0.34614756 | G21: 0.44817112 | H21: 0.45817689 | I21: 0.35944729 | J21: 0.36862334 | K21: 0.45028 | L21: 0.5637335 | M21: 0.29358703 | N21: 0.55460206 | O21: 0.34316507 | P21: 0.50826183 | Q21: 0.32686052 | R21: 0.4941206 | S21: 0.38587108 | T21: 0.35963491 | U21: 0.5637572 | V21: 0.2824558 | W21: 0.64750337 | X21: 0.38943535 | Y21: 0.54088534 | Z21: 0.4012808 | AA21: 0.45065358 | AD21: is the reconstruction error
C22: Decreasing | D22: 0.68926329 | E22: 0.11994801 | F22: 0.68164964 | G22: 0.1461065 | H22: 0.75220007 | I22: 0.074699907 | J22: 0.77451918 | K22: 0.065257487 | L22: 0.78377692 | M22: 0.082965342 | N22: 0.78545694 | O22: 0.094584499 | P22: 0.75800874 | Q22: 0.12988854 | R22: 0.78597927 | S22: 0.086905255 | T22: 0.71879558 | U22: 0.1699708 | V22: 0.63985672 | W22: 0.24040276 | X22: 0.5235756 | Y22: 0.3204772 | Z22: 0.72975596 | AA22: 0.13501658 | AD22: is the measured output
C23: Lower | D23: 0.41602032 | E23: 0.32985986 | F23: 0.36231817 | G23: 0.36515649 | H23: 0.54674337 | I23: 0.2755751 | J23: 0.50545274 | K23: 0.30164592 | L23: 0.52472203 | M23: 0.29715228 | N23: 0.47096897 | O23: 0.30944664 | P23: 0.58124379 | Q23: 0.26094128 | R23: 0.60520401 | S23: 0.24844166 | T23: 0.60373542 | U23: 0.25208398 | V23: 0.34743453 | W23: 0.47621336 | X23: 0.34711129 | Y23: 0.44864166 | Z23: 0.48839641 | AA23: 0.32111286
B24: sineOptM | C24: Upper | D24: 0.46669256 | E24: 0.22955017 | F24: 0.4816925 | G24: 0.26075616 | H24: 0.47844254 | I24: 0.29695492 | J24: 0.45521375 | K24: 0.31393214 | L24: 0.51805149 | M24: 0.27996972 | N24: 0.45956037 | O24: 0.38710866 | P24: 0.51020996 | Q24: 0.33861595 | R24: 0.28590179 | S24: 0.56716389 | T24: 0.21751858 | U24: 0.6310243 | V24: 0.2506924 | W24: 0.57554691 | X24: 0.12027032 | Y24: 0.68735421 | Z24: 0.40167529 | AA24: 0.40217158
C25: Decreasing | D25: 0.65949854 | E25: 0.14200328 | F25: 0.69967776 | G25: 0.12147116 | H25: 0.71385881 | I25: 0.11840928 | J25: 0.74192338 | K25: 0.10632154 | L25: 0.74973576 | M25: 0.11461727 | N25: 0.73979661 | O25: 0.14661579 | P25: 0.75303959 | Q25: 0.13257148 | R25: 0.70046932 | S25: 0.20581618 | T25: 0.64026593 | U25: 0.24320926 | V25: 0.59856697 | W25: 0.23694732 | X25: 0.48597606 | Y25: 0.36373676 | Z25: 0.69261285 | AA25: 0.16763321
C26: Lower | D26: 0.48355054 | E26: 0.30032377 | F26: 0.49026355 | G26: 0.27811645 | H26: 0.52001102 | I26: 0.26874035 | J26: 0.55642849 | K26: 0.24503649 | L26: 0.58471803 | M26: 0.24092802 | N26: 0.56552623 | O26: 0.26882993 | P26: 0.54965299 | Q26: 0.27782175 | R26: 0.54692307 | S26: 0.29858724 | T26: 0.52446128 | U26: 0.29562146 | V26: 0.47284348 | W26: 0.3570139 | X26: 0.42412753 | Y26: 0.37317293 | Z26: 0.51605231 | AA26: 0.2929954
B27: 3sineNlcOptM | C27: Upper | D27: 0.53864048 | E27: 0.23932598 | F27: 0.58522556 | G27: 0.21807844 | H27: 0.63504088 | I27: 0.19132651 | J27: 0.59467554 | K27: 0.26706349 | L27: 0.62975865 | M27: 0.24498611 | N27: 0.60108562 | O27: 0.28671464 | P27: 0.6141089 | Q27: 0.28272342 | R27: 0.59746388 | S27: 0.31043936 | T27: 0.64649735 | U27: 0.25031039 | V27: 0.54946944 | W27: 0.33030958 | X27: 0.49547323 | Y27: 0.38865533 | Z27: 0.58041264 | AA27: 0.28689978
C28: Decreasing | D28: 0.70762873 | E28: 0.094494619 | F28: 0.73463276 | G28: 0.086219618 | H28: 0.75743347 | I28: 0.080827663 | J28: 0.77072735 | K28: 0.082168169 | L28: 0.79132371 | M28: 0.071215374 | N28: 0.79489443 | O28: 0.076424217 | P28: 0.80470084 | Q28: 0.072189806 | R28: 0.80206984 | S28: 0.069813141 | T28: 0.73088744 | U28: 0.1406705 | V28: 0.66102804 | W28: 0.19640987 | X28: 0.61606455 | Y28: 0.20456713 | Z28: 0.75083339 | AA28: 0.1088989
C29: Lower | D29: 0.60999147 | E29: 0.18240193 | F29: 0.61101363 | G29: 0.19762866 | H29: 0.63859689 | I29: 0.18007207 | J29: 0.67423854 | K29: 0.16457029 | L29: 0.6831063 | M29: 0.16435192 | N29: 0.70267589 | O29: 0.1534627 | P29: 0.70307862 | Q29: 0.15887604 | R29: 0.66476046 | S29: 0.2310808 | T29: 0.65993004 | U29: 0.21227624 | V29: 0.67401723 | W29: 0.1679054 | X29: 0.63416326 | Y29: 0.20243681 | Z29: 0.65633543 | AA29: 0.18924301
B30: 3sineOptM | C30: Upper | D30: 0.54310075 | E30: 0.24120057 | F30: 0.61313816 | G30: 0.1933477 | H30: 0.6369678 | I30: 0.19475688 | J30: 0.62914598 | K30: 0.23806198 | L30: 0.62519888 | M30: 0.25992503 | N30: 0.61360208 | O30: 0.26662345 | P30: 0.63706126 | Q30: 0.24951506 | R30: 0.54591911 | S30: 0.3535584 | T30: 0.5959751 | U30: 0.29167874 | V30: 0.52724113 | W30: 0.35000013 | X30: 0.48826341 | Y30: 0.37518737 | Z30: 0.58871218 | AA30: 0.2729527 | AD30: Nb samples per cycle phase | AH30: The phase cycle are sorted
C31: Decreasing | D31: 0.71119624 | E31: 0.09763366 | F31: 0.74569415 | G31: 0.073512977 | H31: 0.76597269 | I31: 0.071574726 | J31: 0.78542835 | K31: 0.072075275 | L31: 0.80293469 | M31: 0.069002199 | N31: 0.80882723 | O31: 0.061559964 | P31: 0.81325564 | Q31: 0.064351936 | R31: 0.81294563 | S31: 0.057490859 | T31: 0.76210185 | U31: 0.1216281 | V31: 0.66989997 | W31: 0.18974728 | X31: 0.59852106 | Y31: 0.22402359 | Z31: 0.76511395 | AA31: 0.09960908 | AC31: Upper | AD31: 45 | AH31: offline using the same methodology
C32: Lower | D32: 0.57510929 | E32: 0.2038134 | F32: 0.59810889 | G32: 0.20272732 | H32: 0.62945242 | I32: 0.19193804 | J32: 0.6675539 | K32: 0.17357382 | L32: 0.67915571 | M32: 0.14861763 | N32: 0.68502611 | O32: 0.16815923 | P32: 0.70922348 | Q32: 0.14683708 | R32: 0.68866523 | S32: 0.18377762 | T32: 0.62996582 | U32: 0.24758469 | V32: 0.6611399 | W32: 0.19081204 | X32: 0.60525625 | Y32: 0.23874274 | Z32: 0.64385748 | AA32: 0.19875949 | AC32: Decreas. | AD32: 54 | AH32: as in virtual force estimation tab
B33: 2sineNlcOptM | C33: Upper | D33: 0.4405264 | E33: 0.29197252 | F33: 0.4132256 | G33: 0.36438679 | H33: 0.48000207 | I33: 0.28039611 | J33: 0.53621662 | K33: 0.26262822 | L33: 0.50839979 | M33: 0.25839838 | N33: 0.53661935 | O33: 0.28550594 | P33: 0.55603279 | Q33: 0.31712085 | R33: 0.47698543 | S33: 0.34679738 | T33: 0.42956633 | U33: 0.45435313 | V33: 0.36484363 | W33: 0.43014883 | X33: 0.2823955 | Y33: 0.51309972 | Z33: 0.44279664 | AA33: 0.36586143 | AC33: Lower | AD33: 56
C34: Decreasing | D34: 0.6748129 | E34: 0.11165575 | F34: 0.72261031 | G34: 0.094279923 | H34: 0.74044619 | I34: 0.081564241 | J34: 0.74481858 | K34: 0.084512919 | L34: 0.79196086 | M34: 0.06018002 | N34: 0.77685159 | O34: 0.090329135 | P34: 0.78267576 | Q34: 0.1010388 | R34: 0.78783351 | S34: 0.084092612 | T34: 0.77025225 | U34: 0.10447558 | V34: 0.66773516 | W34: 0.21377056 | X34: 0.57549417 | Y34: 0.26659782 | Z34: 0.73925845 | AA34: 0.1161369 | AC34: total | AD34: =SUM(AD31:AD33) -> 155
C35: Lower | D35: 0.63341439 | E35: 0.14727019 | F35: 0.6566732 | G35: 0.15920361 | H35: 0.6728072 | I35: 0.16477141 | J35: 0.67730591 | K35: 0.13300592 | L35: 0.67738779 | M35: 0.15773157 | N35: 0.69416325 | O35: 0.15141274 | P35: 0.66807267 | Q35: 0.19681828 | R35: 0.68090562 | S35: 0.16112887 | T35: 0.63481282 | U35: 0.22293498 | V35: 0.56603966 | W35: 0.27351113 | X35: 0.5932066 | Y35: 0.23702811 | Z35: 0.6516928 | AA35: 0.18496938
B36: 2sineOptM | C36: Upper | D36: 0.52460555 | E36: 0.25050741 | F36: 0.60543807 | G36: 0.20628047 | H36: 0.62013591 | I36: 0.19918156 | J36: 0.60589699 | K36: 0.24470377 | L36: 0.64285046 | M36: 0.24714803 | N36: 0.61462346 | O36: 0.25067289 | P36: 0.58837982 | Q36: 0.30322767 | R36: 0.50919872 | S36: 0.40055032 | T36: 0.61205917 | U36: 0.29259295 | V36: 0.50060605 | W36: 0.41618504 | X36: 0.54595265 | Y36: 0.33763932 | Z36: 0.57425589 | AA36: 0.29233099
C37: Decreasing | D37: 0.71873694 | E37: 0.092405965 | F37: 0.74882244 | G37: 0.08016995 | H37: 0.76763454 | I37: 0.073268095 | J37: 0.78981761 | K37: 0.064297088 | L37: 0.8064496 | M37: 0.056590285 | N37: 0.82174564 | O37: 0.041483928 | P37: 0.81723558 | Q37: 0.053505524 | R37: 0.8059383 | S37: 0.06786293 | T37: 0.7757528 | U37: 0.094775317 | V37: 0.71698968 | W37: 0.13694965 | X37: 0.62532483 | Y37: 0.21054734 | Z37: 0.77017061 | AA37: 0.0932366
C38: Lower | D38: 0.63800347 | E38: 0.17349662 | F38: 0.66618244 | G38: 0.16029456 | H38: 0.67323102 | I38: 0.16663697 | J38: 0.69677933 | K38: 0.15791907 | L38: 0.70809311 | M38: 0.14520457 | N38: 0.7298931 | O38: 0.14320874 | P38: 0.7344229 | Q38: 0.14974913 | R38: 0.70456491 | S38: 0.18720993 | T38: 0.74033259 | U38: 0.13630499 | V38: 0.71739554 | W38: 0.15910403 | X38: 0.63981256 | Y38: 0.22000803 | Z38: 0.6917686 | AA38: 0.170739
B39: Total | C39: Upper | D39: 0.45689213 | E39: 0.28781007 | F39: 0.48206074 | G39: 0.30677579 | H39: 0.52045725 | I39: 0.28730578 | J39: 0.51650889 | K39: 0.30737043 | L39: 0.54191012 | M39: 0.29835999 | N39: 0.53695082 | O39: 0.32186474 | P39: 0.51888058 | Q39: 0.34967378 | R39: 0.49553377 | S39: 0.37305065 | T39: 0.47269148 | U39: 0.40101063 | V39: 0.39140546 | W39: 0.4795888 | X39: 0.32299732 | Y39: 0.53421113 | Z39: 0.46891263 | AA39: 0.37023164
C40: Decreasing | D40: 0.67836799 | E40: 0.12721833 | F40: 0.71123881 | G40: 0.10861365 | H40: 0.73575054 | I40: 0.095664608 | J40: 0.75816139 | K40: 0.090493537 | L40: 0.76952961 | M40: 0.098548661 | N40: 0.78006724 | O40: 0.098707755 | P40: 0.79336821 | Q40: 0.090553349 | R40: 0.76791054 | S40: 0.12005871 | T40: 0.69801715 | U40: 0.18927611 | V40: 0.63306316 | W40: 0.23072847 | X40: 0.56285922 | Y40: 0.28216081 | Z40: 0.72033366 | AA40: 0.14454134
C41: Lower | D41: 0.53989531 | E41: 0.23279039 | F41: 0.55267496 | G41: 0.23555399 | H41: 0.55784017 | I41: 0.25415268 | J41: 0.58292119 | K41: 0.24394901 | L41: 0.58509798 | M41: 0.2466637 | N41: 0.57637758 | O41: 0.26704306 | P41: 0.60591903 | Q41: 0.25100981 | R41: 0.57981094 | S41: 0.27755038 | T41: 0.56652725 | U41: 0.2861708 | V41: 0.50413835 | W41: 0.34032253 | X41: 0.46017161 | Y41: 0.35569439 | Z41: 0.55208435 | AA41: 0.27740762
...

Sheet virtual force estimation
P2: Method | Q2: Cycle phase | R2: avg | S2: std
C3: phase | P3: filter+ | Q3: Upper | R3: =C5 -> 0.70776581 | S3: =D5 -> 0.087465688
B4: Method | C4: upper | E4: decreasing | G4: lower | Q4: Decreasing | R4: =E5 -> 0.74615355 | S4: =F5 -> 0.082782852
B5: filter+ | C5: 0.70776581 | D5: 0.087465688 | E5: 0.74615355 | F5: 0.082782852 | G5: 0.79635903 | H5: 0.08446512 | Q5: Lower | R5: =G5 -> 0.79635903 | S5: =H5 -> 0.08446512
B6: SineOpt+ | C6: 0.42690209 | D6: 0.51410825 | E6: 0.2011412 | F6: 0.78621398 | G6: 0.055314178 | H6: 0.79548996 | P6: SineOpt+ | Q6: Upper | R6: =C6 -> 0.42690209 | S6: =D6 -> 0.51410825
B7: 5sineOpt+ | C7: 0.69712839 | D7: 0.19970173 | E7: 0.74772881 | F7: 0.17786872 | G7: 0.66848531 | H7: 0.24868502 | Q7: Decreasing | R7: =E6 -> 0.2011412 | S7: =F6 -> 0.78621398
B8: 5sineNlcOpt+ | C8: -0.62191277 | D8: 1.7696544 | E8: 0.64801772 | F8: 0.28844902 | G8: 0.2272447 | H8: 0.80768157 | Q8: Lower | R8: =G6 -> 0.055314178 | S8: =H6 -> 0.79548996
B9: 3sineOpt+ | C9: 0.22607817 | D9: 0.69869633 | E9: 0.1593567 | F9: 0.77071364 | G9: 0.15307719 | H9: 0.67358643 | P9: 5sineOpt+ | Q9: Upper | R9: =C7 -> 0.69712839 | S9: =D7 -> 0.19970173
B10: 3sineNlcOpt+ | C10: -1.645351 | D10: 2.2790385 | E10: 0.0012159404 | F10: 0.88599589 | G10: -0.65381728 | H10: 1.6962598 | Q10: Decreasing | R10: =E7 -> 0.74772881 | S10: =F7 -> 0.17786872
B11: sineOptM | C11: 0.75620412 | D11: 0.15061594 | E11: 0.787335 | F11: 0.13609235 | G11: 0.6829241 | H11: 0.24171247 | Q11: Lower | R11: =G7 -> 0.66848531 | S11: =H7 -> 0.24868502
B12: 3sineNlcOptM | C12: 0.81432087 | D12: 0.11187235 | E12: 0.81118018 | F12: 0.12139451 | G12: 0.76405952 | H12: 0.16714471 | P12: 5sineNlcOpt+ | Q12: Upper | R12: =C8 -> -0.62191277 | S12: =D8 -> 1.7696544
B13: 3sineOptM | C13: 0.78903424 | D13: 0.12676512 | E13: 0.81079104 | F13: 0.12078899 | G13: 0.7267425 | H13: 0.20368079 | Q13: Decreasing | R13: =E8 -> 0.64801772 | S13: =F8 -> 0.28844902
B14: 2sineNlcOptM | C14: 0.74352814 | D14: 0.14396504 | E14: 0.84214142 | F14: 0.089238084 | G14: 0.79234973 | H14: 0.13612006 | Q14: Lower | R14: =G8 -> 0.2272447 | S14: =H8 -> 0.80768157
B15: 2sineOptM | C15: 0.808542 | D15: 0.11589941 | E15: 0.84021149 | F15: 0.097905146 | G15: 0.76623367 | H15: 0.17626118 | L15: =INDIRECT({"'position reconstruction 2'!D6";"'position reconstruction 2'!D9";"'position reconstruction 2'!D12";"'position reconstruction 2'!D15";"'position reconstruction 2'!D18";"'position reconstruction 2'!D21";"'position reconstruction 2'!D24";"'position reconstruction 2'!D27";"'position reconstruction 2'!D30";"'position reconstruction 2'!D33";"'position reconstruction 2'!D36"}) -> 0.55433421 | P15: 3sineOpt+ | Q15: Upper | R15: =C9 -> 0.22607817 | S15: =D9 -> 0.69869633
L16: =INDIRECT({"'position reconstruction 2'!D9";"'position reconstruction 2'!D12";"'position reconstruction 2'!D15";"'position reconstruction 2'!D18";"'position reconstruction 2'!D21";"'position reconstruction 2'!D24";"'position reconstruction 2'!D27";"'position reconstruction 2'!D30";"'position reconstruction 2'!D33";"'position reconstruction 2'!D36"}) -> 0.46553523 | Q16: Decreasing | R16: =E9 -> 0.1593567 | S16: =F9 -> 0.77071364
Q17: Lower | R17: =G9 -> 0.15307719 | S17: =H9 -> 0.67358643
B18: Phase | C18: upper | D18: decreasing | E18: lower | L18: =CONCATENATE('position reconstruction 2'!D6,'position reconstruction 2'!D9,'position reconstruction 2'!D12,'position reconstruction 2'!D15,'position reconstruction 2'!D18,'position reconstruction 2'!D21,'position reconstruction 2'!D24,'position reconstruction 2'!D27,'position reconstruction 2'!D30,'position reconstruction 2'!D33,'position reconstruction 2'!D36) -> 0,5543342084479630,4655352292645650,3580013433337650,3688283298941590,4848577557906410,3431962425864320,466692564398060,5386404764758630,543100745842070,4405263952108760,524605552525311 | P18: 3sineNlcOpt+ | Q18: Upper | R18: =C10 -> -1.645351 | S18: =D10 -> 2.2790385
B19: Correlation | C19: =CORREL(C5:C15,D5:D15) -> -0.98817047 | D19: =CORREL(E5:E15,F5:F15) -> -0.99278532 | E19: =CORREL(G5:G15,H5:H15) -> -0.99188635 | Q19: Decreasing | R19: =E10 -> 0.0012159404 | S19: =F10 -> 0.88599589
Q20: Lower | R20: =G10 -> -0.65381728 | S20: =H10 -> 1.6962598
D21: Correlation between accuracy in trajectory prediction and fit after position reconstruction using identified impedance parameters | P21: sineOptM | Q21: Upper | R21: =C11 -> 0.75620412 | S21: =D11 -> 0.15061594
D22: delay (ms) | Q22: Decreasing | R22: =E11 -> 0.787335 | S22: =F11 -> 0.13609235
C23: Phase | D23: 5 | E23: 6 | F23: 7 | G23: 8 | H23: 9 | I23: 10 | J23: 11 | K23: 12 | L23: 13 | M23: 14 | N23: 15 | Q23: Lower | R23: =G11 -> 0.6829241 | S23: =H11 -> 0.24171247
C24: Upper | D24: =CORREL('position reconstruction 2'!D51:D61,'virtual force estimation'!C5:C15) -> 0.68760742 | P24: 3sineNlcOptM | Q24: Upper | R24: =C12 -> 0.81432087 | S24: =D12 -> 0.11187235
C25: Decreasing | D25: =CORREL('position reconstruction 2'!E51:E61,'virtual force estimation'!E5:E15) -> 0.069098373 | Q25: Decreasing | R25: =E12 -> 0.81118018 | S25: =F12 -> 0.12139451
C26: Lower | D26: =CORREL('position reconstruction 2'!F51:F61,'virtual force estimation'!G5:G15) -> 0.77713661 | Q26: Lower | R26: =G12 -> 0.76405952 | S26: =H12 -> 0.16714471
C27: Total | D27: =CORREL('position reconstruction 2'!D6:D38,'virtual force estimation'!$R3:$R35) -> 0.51533563 | E27: =CORREL('position reconstruction 2'!F6:F38,'virtual force estimation'!$R3:$R35) -> 0.57099869 | F27: =CORREL('position reconstruction 2'!H6:H38,'virtual force estimation'!$R3:$R35) -> 0.45432558 | G27: =CORREL('position reconstruction 2'!J6:J38,'virtual force estimation'!$R3:$R35) -> 0.4923845 | H27: =CORREL('position reconstruction 2'!L6:L38,'virtual force estimation'!$R3:$R35) -> 0.32428533 | I27: =CORREL('position reconstruction 2'!N6:N38,'virtual force estimation'!$R3:$R35) -> 0.40623232 | J27: =CORREL('position reconstruction 2'!P6:P38,'virtual force estimation'!$R3:$R35) -> 0.31136495 | K27: =CORREL('position reconstruction 2'!Q6:Q38,'virtual force estimation'!$R3:$R35) -> -0.27672161 | L27: =CORREL('position reconstruction 2'!S6:S38,'virtual force estimation'!$R3:$R35) -> -0.23694636 | M27: =CORREL('position reconstruction 2'!U6:U38,'virtual force estimation'!$R3:$R35) -> -0.37462319 | N27: =CORREL('position reconstruction 2'!W6:W38,'virtual force estimation'!$R3:$R35) -> -0.43039545 | P27: 3sineOptM | Q27: Upper | R27: =C13 -> 0.78903424 | S27: =D13 -> 0.12676512
Q28: Decreasing | R28: =E13 -> 0.81079104 | S28: =F13 -> 0.12078899
Q29: Lower | R29: =G13 -> 0.7267425 | S29: =H13 -> 0.20368079
P30: 2sineNlcOptM | Q30: Upper | R30: =C14 -> 0.74352814 | S30: =D14 -> 0.14396504
D31: =CORREL((MOD(ROW('virtual force estimation'!D6:D38),3)=0)*('virtual force estimation'!D6:D38),C5:C15) -> #N/A | Q31: Decreasing | R31: =E14 -> 0.84214142 | S31: =F14 -> 0.089238084
Q32: Lower | R32: =G14 -> 0.79234973 | S32: =H14 -> 0.13612006
P33: 2sineOptM | Q33: Upper | R33: =C15 -> 0.808542 | S33: =D15 -> 0.11589941
Q34: Decreasing | R34: =E15 -> 0.84021149 | S34: =F15 -> 0.097905146
Q35: Lower | R35: =G15 -> 0.76623367 | S35: =H15 -> 0.17626118
